Workbook

Sheet Инструкция
A1: Опрос: узкие места при предоставлении доступов к ИС и ИР
A3: Цель — собрать фактические сроки и особенности работы с заявками в подразделениях и у разных заказчиков, выявить задержки по этапам жизненного цикла.
A5: Контекст процесса
A6: • При трудоустройстве после подписания приказа и ознакомления с регламентами (отметка сотрудника ИБ в КИС Доступ) выдаётся базовый пакет: доменная УЗ, электронная почта, базовый доступ к СЭД. • Остальные доступы — по заявкам (собственные ИС и ресурсы заказчиков). • Жизненный цикл заявки: 1) подготовка и запуск в СЭД; 2) согласование в СЭД и устранение замечаний; 3) передача из СЭД на исполнение в КАСПП корпоративному оператору ИТ (КОИТ).
A8: Точка отсчёта X
A9: X — момент приёма сотрудника в организацию (дата из приказа о приёме / фактический первый рабочий день — укажите в листе «Кейсы» единообразно для всех строк кейса). Все поля «от X, раб.ч» — накопленное рабочее время от точки X до наступления события (с учётом только рабочих часов: пн–пт, 09:00–18:00, без праздников; при другом графике подразделения — укажите в листе «Подразделения»).
A11: Как заполнять
A12: 1. Лист «Подразделения» — одна анкета на отвечающее подразделение. 2. Лист «Кейсы» — типовые ситуации приёма сотрудника, дата точки X, сроки базового пакета. 3. Лист «Заявки» — каждый блок = одна заявка на доступ; укажите зависимости, длительности этапов в рабочих часах и моменты от X. 4. Лист «Особенности» — качественные наблюдения по шаблонам, согласующим и заказчикам.
A14: Поля длительности (раб.ч)
A15: «Длит. этапа, раб.ч» — чистое время этапа (без параллельного ожидания вне этапа). «Ожидание, раб.ч» — простой внутри этапа (очередь, отсутствие согласующего и т.п.). Если точные даты неизвестны — оцените по последним 3–5 аналогичным случаям (мин / тип / макс).
A17: Зависимости заявок
A18: Если запуск заявки возможен только после другой заявки или появления доменной УЗ — укажите ID зависимой заявки или «Базовый пакет: доменная УЗ» в соответствующих колонках. Отдельно зафиксируйте задержку из-за зависимости в «Ожидание зависимости, раб.ч».

Sheet Подразделения
A1: филиал г. Омск
A2: Поле | B2: Значение
A3: ID подразделения | B3: 03-Омск
A4: Наименование подразделения | B4: Филиал в г. Омск
A5: Контактное лицо (ФИО)
A6: Должность
A7: E-mail / телефон
A8: Рабочий график для расчёта (если не 09–18 пн–пт)
A9: Среднее число новых сотрудников в месяц
A10: Доля заявок на системы заказчиков, %
A11: Используемый шаблон/маршрут СЭД для доступов
A12: Типовые согласующие (роли)
A13: Комментарий по особенностям процесса

Sheet Кейсы
A1: Кейс №1
A2: Поле | B2: Значение
A3: ID кейса
A4: ID подразделения | B4: =Подразделения!$B$3 -> 03-Омск
A5: Тип кейса (новый сотрудник / перевод / подрядчик / иное)
A6: Дата точки X (приём в организацию)
A7: Определение точки X в кейсе
A8: Приказ подписан: от X, раб.ч
A9: Ознакомление с регламентами (КИС Доступ, ИБ): от X, раб.ч
A10: Базовый пакет полностью выдан: от X, раб.ч
A11: Доменная УЗ: от X, раб.ч
A12: Почта: от X, раб.ч
A13: Базовый СЭД: от X, раб.ч
A14: Задержка базового пакета, раб.ч (если была)
A15: Причина задержки базового пакета
A16: Число доп. заявок в кейсе
... A19: Кейс №2
A20: Поле | B20: Значение
A21: ID кейса
A22: ID подразделения | B22: =Подразделения!$B$3 -> 03-Омск
A23: Тип кейса (новый сотрудник / перевод / подрядчик / иное)
A24: Дата точки X (приём в организацию)
A25: Определение точки X в кейсе
A26: Приказ подписан: от X, раб.ч
A27: Ознакомление с регламентами (КИС Доступ, ИБ): от X, раб.ч
A28: Базовый пакет полностью выдан: от X, раб.ч
A29: Доменная УЗ: от X, раб.ч
A30: Почта: от X, раб.ч
A31: Базовый СЭД: от X, раб.ч
A32: Задержка базового пакета, раб.ч (если была)
A33: Причина задержки базового пакета
A34: Число доп. заявок в кейсе
... A37: Кейс №3
A38: Поле | B38: Значение
A39: ID кейса
A40: ID подразделения | B40: =Подразделения!$B$3 -> 03-Омск
A41: Тип кейса (новый сотрудник / перевод / подрядчик / иное)
A42: Дата точки X (приём в организацию)
A43: Определение точки X в кейсе
A44: Приказ подписан: от X, раб.ч
...

Sheet Заявки
A1: Заявка №1
A2: Поле | B2: Значение
A3: ID заявки
A4: ID кейса
A5: ID подразделения | B5: =Подразделения!$B$3 -> 03-Омск
A6: Собственная / Заказчика
A7: Заказчик
A8: Система / ресурс
A9: Тип заявки (из справочника или свой)
A10: Критичность для начала работы
A11: Зависит от (ID заявки или «Базовый пакет: …»)
A12: Можно подать до выдачи базового пакета?
A13: Факт старта подготовки: от X, раб.ч
A14: Э1: длит. подготовки, раб.ч
A15: Э1: ожидание, раб.ч
A16: Э1: запуск в СЭД: от X, раб.ч
A17: Э2: длит. согласования, раб.ч
... A31: Заявка №2
A32: Поле | B32: Значение
A33: ID заявки
A34: ID кейса
A35: ID подразделения | B35: =Подразделения!$B$3 -> 03-Омск
A36: Собственная / Заказчика
A37: Заказчик
A38: Система / ресурс
A39: Тип заявки (из справочника или свой)
A40: Критичность для начала работы
A41: Зависит от (ID заявки или «Базовый пакет: …»)
A42: Можно подать до выдачи базового пакета?
A43: Факт старта подготовки: от X, раб.ч
A44: Э1: длит. подготовки, раб.ч
A45: Э1: ожидание, раб.ч
A46: Э1: запуск в СЭД: от X, раб.ч
A47: Э2: длит. согласования, раб.ч
... A61: Заявка №3
A62: Поле | B62: Значение
A63: ID заявки
A64: ID кейса
A65: ID подразделения | B65: =Подразделения!$B$3 -> 03-Омск
A66: Собственная / Заказчика
...

Sheet Особенности
A1: Запись №1
A2: Поле | B2: Значение
A3: ID записи
A4: ID подразделения | B4: =Подразделения!$B$3 -> 03-Омск
A5: Заказчик (если применимо)
A6: Категория
A7: Описание особенности / проблемы
A8: Как сейчас обходят
A9: Предложение по улучшению
A10: Влияние на срок (оценка, раб.ч)
A12: Запись №2
A13: Поле | B13: Значение
A14: ID записи
A15: ID подразделения | B15: =Подразделения!$B$3 -> 03-Омск
A16: Заказчик (если применимо)
A17: Категория
A18: Описание особенности / проблемы
A19: Как сейчас обходят
A20: Предложение по улучшению
A21: Влияние на срок (оценка, раб.ч)
A23: Запись №3
A24: Поле | B24: Значение
A25: ID записи
A26: ID подразделения | B26: =Подразделения!$B$3 -> 03-Омск
A27: Заказчик (если применимо)
A28: Категория
A29: Описание особенности / проблемы
A30: Как сейчас обходят
A31: Предложение по улучшению
A32: Влияние на срок (оценка, раб.ч)
A34: Запись №4
A35: Поле | B35: Значение
A36: ID записи
A37: ID подразделения | B37: =Подразделения!$B$3 -> 03-Омск
A38: Заказчик (если применимо)
A39: Категория
A40: Описание особенности / проблемы
A41: Как сейчас обходят
A42: Предложение по улучшению
A43: Влияние на срок (оценка, раб.ч)
...

Sheet Сводка_для_анализа
A1: Агрегирующие метрики (заполняется аналитиком после сбора опросов)
A3: Метрика | B3: Формула / источник | C3: Значение
A4: Медиана: базовый пакет, раб.ч от X | B4: «Кейсы», поле «Базовый пакет полностью выдан» (вертикальные блоки на листах)
A5: Медиана: полный цикл заявки, раб.ч | B5: «Заявки», поле «Полный цикл заявки» (вертикальные блоки на листах)
A6: Медиана: Э1 подготовка, раб.ч | B6: «Заявки», поле «Э1: длит. подготовки» (вертикальные блоки на листах)
A7: Медиана: Э2 согласование, раб.ч | B7: «Заявки», поле «Э2: длит. согласования» (вертикальные блоки на листах)
A8: Медиана: Э3 КАСПП+КОИТ, раб.ч | B8: Сумма полей Э3 на листе «Заявки» (вертикальные блоки на листах)
A9: Доля заявок с узким местом Э2 | B9: «Заявки», поле «Узкое место» (вертикальные блоки на листах)
A10: Среднее число циклов замечаний | B10: «Заявки», поле «Э2: число циклов замечаний» (вертикальные блоки на листах)
A11: Среднее ожидание зависимостей, раб.ч | B11: «Заявки», поле «Ожидание зависимости» (вертикальные блоки на листах)

Sheet Справочники
A1: Подразделения | C1: Заказчики | E1: Типы_собственные | G1: Типы_заказчика | I1: Да_Нет | K1: Узкие_места | M1: Базовый_пакет | O1: ID Подразделений
A2: ЦА | C2: — (собственные системы) | E2: Доступ к файловым ресурсам собственным | G2: Бухгалтерская Учетная система Заказчика | I2: Да | K2: Этап 1 — подготовка и запуск в СЭД | M2: Доменная учётная запись | O2: 01-ЦА
A3: Филиал в г. Казань | C3: Заказчик Омск 1 | E3: СЭД (расширенный доступ) | G3: Электронная система хранения документов Заказчика | I3: Нет | K3: Этап 2 — согласование и замечания в СЭД | M3: Электронная почта | O3: 02-Казань
A4: Филиал в г. Омск | C4: Заказчик Казань 1 | E4: Удаленный доступ к ресурсам ККС | G4: Доступ к файловым ресурсам Заказчика | I4: Не применимо | K4: Этап 3 — исполнение в КАСПП (КОИТ) | M4: Базовый доступ к СЭД | O4: 03-Омск
A5: Филиал в г. Самара | C5: Заказчик Самара 1 | G5: Прочие ресурсы Заказчика | K5: Ожидание зависимой заявки / УЗ | O5: 04-Самара
A6: Филиал в г. Новороссийск | C6: Заказчик Омск 2 | K6: Ожидание действий заказчика | O6: 05-Новороссийск
A7: Филиал в г. Брянск | C7: Заказчик Казань 2 | K7: Ожидание действий подразделения | O7: 06-Брянск
A8: Филиал в г. Нижний Новгород | C8: Заказчик Самара 2 | K8: Не выявлено | O8: 07-Нижний Новгород
C9: Заказчик Омск 3
C10: Заказчик Казань 3
C11: Заказчик Самара 3
